Workbook

Sheet LCA Dashboard
A1: LCA DASHBOARD | PET vs ALUMINIUM PACKAGING
A3: Cradle-to-gate climate-change screening • Functional unit: primary packaging for 1 L beverage • kg CO₂e/FU
A5: BASE CASE | PET BOTTLE | F5: BASE CASE | ALUMINIUM CAN | K5: COMPARATIVE RATIO
A6: =LCIA!C18 -> 0.068407338 | F6: =LCIA!D18 -> 0.24318152 | K6: =IFERROR(LCIA!D18/LCIA!C18,0) -> 3.554904
A8: 1 × 1 L PET bottle + closure | F8: 4 × 250 mL aluminium cans | K8: Aluminium / PET, base case
A10: LIFE-CYCLE STAGE CONTRIBUTIONS
A11: Stage | B11: PET GWP | C11: Aluminium GWP
A12: Material production | B12: =SUM(LCIA!C3:C8) -> 0.057434 | C12: =SUM(LCIA!D3:D8) -> 0.19739114
A13: Sheet rolling | B13: =LCIA!C9 -> 0 | C13: =LCIA!D9 -> 0.01699088
A14: Material transport | B14: =SUM(LCIA!C10:C12) -> 0.001630775 | C14: =SUM(LCIA!D10:D12) -> 0.00221665
A15: Package manufacturing | B15: =SUM(LCIA!C13:C16) -> 0.0093425625 | C15: =SUM(LCIA!D13:D16) -> 0.026582852
A18: RECYCLED CONTENT | INTERACTIVE EXPLORER
A19: Parameter | B19: PET | C19: Aluminium
A20: Recycled content | B20: 0.25 | C20: ='Sensitivity Analysis'!C9 -> 0.54 | D20: ← Change yellow cells
A21: Virgin fraction | B21: =1-B20 -> 0.75 | C21: =1-C20 -> 0.46 | D21: Automatically calculated
A22: Modelled GWP | B22: ='Sensitivity Analysis'!B5*(B21*'Sensitivity Analysis'!B6+B20*'Sensitivity Analysis'!B7)+'Sensitivity Analysis'!B8 -> 0.068407338 | C22: ='Sensitivity Analysis'!C5*(C21*'Sensitivity Analysis'!C6+C20*'Sensitivity Analysis'!C7)+'Sensitivity Analysis'!C8 -> 0.24318152 | D22: kg CO₂e/FU
A24: Scenario comparison | B24: PET GWP | C24: Aluminium GWP
A25: Low recycled | B25: ='Sensitivity Analysis'!E13 -> 0.076667338 | C25: ='Sensitivity Analysis'!E19 -> 0.36086398
A26: Base case | B26: ='Sensitivity Analysis'!E14 -> 0.068407338 | C26: ='Sensitivity Analysis'!E20 -> 0.24318152
A27: High recycled | B27: ='Sensitivity Analysis'!E15 -> 0.060147338 | C27: ='Sensitivity Analysis'!E21 -> 0.15796318
A28: Custom scenario | B28: =B22 -> 0.068407338 | C28: =C22 -> 0.24318152
A31: CHANGE RELATIVE TO BASE CASE | + INCREASE / − REDUCTION
A32: Scenario | B32: PET change | C32: Aluminium change
A33: Low recycled | B33: ='Sensitivity Analysis'!F13 -> 0.12074728 | C33: ='Sensitivity Analysis'!F19 -> 0.48392849
A34: Base case | B34: ='Sensitivity Analysis'!F14 -> 0 | C34: ='Sensitivity Analysis'!F20 -> 0
A35: High recycled | B35: ='Sensitivity Analysis'!F15 -> -0.12074728 | C35: ='Sensitivity Analysis'!F21 -> -0.35043097
A36: Custom scenario | B36: =IFERROR(B22/LCIA!C18-1,0) -> 0 | C36: =IFERROR(C22/LCIA!D18-1,0) -> 0
A39: HOTSPOTS | BASE CASE
A40: Indicator | B40: PET | C40: Aluminium
A41: Dominant process | B41: Virgin PET | C41: Primary aluminium
A42: Share of total GWP | B42: =IFERROR(LCIA!C3/LCIA!C18,0) -> 0.6722963 | C42: =IFERROR(LCIA!D6/LCIA!D18,0) -> 0.7878931
A45: METHOD NOTE | Custom scenarios change recycled-content fractions only; mass, transport, manufacturing and selected EFs remain fixed.
A46: Scope: climate change only; cradle-to-gate. Recycled aluminium EF is a remelting proxy; PET preform energy and aluminium losses are not fully captured.

Sheet Goal
B1: Goal Definition
B2: This study conducts a comparative screening life cycle assessment of PET and aluminium beverage packaging to evaluate and compare their cradle-to-gate climate-change impacts for providing an equivalent beverage-packaging function. The aim is to identify the principal life-cycle inputs and processes driving each packaging alternative's greenhouse-gas impacts and to investigate how recycled-content assumptions influence the comparative results.
B3: Guiding question | C3: For packaging required to deliver 1L of beverage, how does the cradle-to-gate climate-change impact of a PET bottle system compare with an aluminium can system, which life-cycle inputs drive the difference, and how sensitive is the comparison to recycled-content assumptions?
B4: Use of finding and audience | C4: The assessment is intended as an educational and portfolio exercise demonstrating the application of the main LCA stages using a transparent Excel-based model and publicly available secondary data. The results are intended for methodological demonstration and exploratory comparison rather than for commercial decision-making or public comparative environmental claims.
B5: Functional unit | C5: Primary packaging required to contain 1 L of beverage
B6: Reference flows for PET and aluminium | C6: PET: 1 × 1 L PET bottle + 1 HDPE closure per FU. Aluminium: 4 × 250 mL complete aluminium cans (including tops) per FU.
B7: System boundary | C7: Cradle-to-gate: raw-material/material production → inbound material transport → package manufacturing → factory gate.
B8: Impact category: climate change, kg CO₂e | C8: Climate change only; results expressed as kg CO₂e per functional unit.
B9: Assumptions, exclusions and limitations | C9: Equivalent containment performance assumed. European secondary data preferred; international proxies used where necessary. End-of-life, beverage production/filling, downstream distribution, refrigeration/use, secondary/tertiary packaging and infrastructure are excluded. Inbound material transport is included as a 500 km road-freight screening assumption applied consistently to both systems.
B12: Framework - ISO 14044
B15: Scope Definition
B16: This comparative screening LCA evaluates the primary packaging required to contain 1 L of beverage using PET bottle and aluminium can systems. The study applies a cradle-to-gate system boundary covering raw-material/material production, inbound transport of packaging materials to the packaging converter/manufacturer, and package manufacturing up to the factory gate. Beverage production, filling, downstream distribution to retailer/customer, refrigeration, consumer use and end-of-life are excluded. The functional unit is the primary packaging required to contain 1 L of beverage. The product alternatives are one 1 L PET bottle with one HDPE closure and four 250 mL complete aluminium cans including tops, providing equivalent beverage-packaging capacity of 1 L. Results therefore represent these specific packaging configurations and should not be interpreted as a universal comparison of PET and aluminium materials. The assessment focuses exclusively on climate-change impact, expressed as kg CO₂e per functional unit. European secondary data are prioritised, supplemented by representative international secondary data where necessary. Recycled content is included as a modelling assumption and will subsequently be examined through sensitivity analysis. Inbound material transport is represented by a controlled 500 km road-freight screening assumption for both systems; this is not a measured supplier route or an official European default. The study is intended as a screening assessment using secondary data and a transparent Excel-based calculation model, rather than a complete multi-impact ISO-conformant comparative LCA.
B17: The product system studied | C17: Beverage packaging: comparative screening life cycle assessment of PET and aluminium beverage packaging to evaluate and compare their cradle-to-gate climate-change impacts for providing an equivalent beverage-packaging function.
B18: Function of the system | C18: To provide primary beverage packaging capable of containing 1 litre of beverage.
B19: The functional unit (FU) | C19: Primary packaging required to contain 1 L of beverage
B20: The system Boundary | C20: Raw-material/material production → inbound material transport → package manufacturing → factory gate

Sheet Functional Unit & Reference Flo
B1: FUNCTIONAL UNIT & REFERENCE FLOW
C3: Functional unit | D3: Reference flow
B4: Package function | C4: Primary packaging for 1Litre of beverage | D4: PET bottle | E4: 1 × 1 L bottle + 1 HDPE closure = 30.34g/FU | F4: 1 PET bottle + closure/FU
B6: To provide primary beverage packaging capable of containing 1 L of beverage. | D6: Aluminium can | E6: 4 × 250 mL complete cans (including tops) 10.31g/can 41.42g/FU | F6: 4 aluminium cans/FU

Sheet System boundary
A2: Item | B2: Current treatment
A3: Functional unit | B3: Primary packaging required to contain 1 L of beverage
A4: PET reference flow | B4: 1 × 1 L PET bottle + 1 HDPE closure
A5: Aluminium reference flow | B5: 4 × 250 mL complete aluminium cans including tops
A6: System boundary | B6: Cradle-to-gate: material production → (Al: sheet rollin) → inbound material transport → packaging conversion/manufacturing → factory gate. PET preform production is physically relevant but its energy coverage is not verified in the selected SBM electricity proxy.
A7: Impact category | B7: Climate change / GWP; kg CO₂e per FU
A8: Transport | B8: 500 km road-freight screening assumption for both systems; not an official EU default

Sheet LCI
B1: Material Required for Packaging systems
A2: System | B2: Material | C2: Qty | D2: Mass
A3: PET | B3: PET bottle body | C3: 1 | D3: 28 | E3: g | F3: =D3/1000 -> 0.028 | G3: kg/FU
B4: HDPE closure | C4: 1 | D4: 2.43 | E4: g | F4: =D4/1000 -> 0.00243 | G4: kg/FU
B5: Pet Bottle/FU | C5: 1 | D5: =SUM(D3:D4) -> 30.43 | E5: g/FU | F5: =D5/1000 -> 0.03043 | G5: kg/FU
A6: Alluminium can | B6: Aluminium can + closure (250 ml) | C6: 1 | D6: 10.31 | E6: g | F6: =D6/1000 -> 0.01031 | G6: kg/FU
B7: Aluminium packaging /FU | C7: 4 | D7: =D6*C7 -> 41.24 | E7: g/FU | F7: =D7/1000 -> 0.04124 | G7: kg/FU
A10: LIFE CYCLE INVENTORY FOR PACKAGING SYSTEMS
A12: PET SYSTEM
A13: Reference Flow | B13: =F5 -> 0.03043 | C13: =G5 -> kg/FU
A14: Stage / process | B14: Packaging System | C14: Flow | D14: Unit | F14: Assumption: HDPE is not recycled
A15: Material production | B15: Virgin PET production | C15: 0.021 | D15: kg/FU
B16: Recycled PET production | C16: 0.007 | D16: kg/FU
B17: Virgin HDPE production | C17: =F4 -> 0.00243 | D17: kg/FU
A18: Inbound transportation | B18: PET resin | C18: 0.014 | D18: tkm/FU
B19: HDPE resin | C19: 0.00117 | D19: tkm/FU
A20: Bottle manufacturing | B20: PET resin | C20: 0.0474432 | D20: kWh/FU
B21: HDPE resin | C21: 0.0034866 | D21: kWh/FU
A26: ALUMINIUM (Al) SYSTEM
A27: Reference Flow | B27: =F7 -> 0.04124 | C27: =G7 -> kg/FU
A28: Stage / process | B28: Packaging System | C28: Flow | D28: Unit | F28: Assumption: No part of Al is lost between material production and sheet roling
A29: Material production | B29: Primary Al | C29: 0.0189704 | D29: kg/FU
B30: Pre-consumption Al | C30: 0.0065984 | D30: kg/FU
B31: Post-consumption Al | C31: 0.0156712 | D31: kg/FU
A32: Sheet Rolling | B32: Al material roll | C32: =F7 -> 0.04124 | D32: =G7 -> kg/FU
A33: Inbound transportation | B33: Road freight | C33: 0.02062 | D33: tkm/FU
A34: Al can production | B34: Electricity | C34: 0.06664384 | D34: kWh/FU
B35: natural gas | C35: 0.217541 | D35: MJ/FU
A39: LIFE CYCLE INVENTORY FOR PACKAGING SYSTEMS
A40: Life Cycle Stage | B40: Process / Input | C40: PET System | D40: Aluminium System | E40: Unit
A41: Reference flow | B41: Packaging mass | C41: 0.03043 | D41: 0.04124 | E41: kg/FU
A43: Material production | B43: Virgin PET production | C43: 0.021 | D43: — | E43: kg/FU
B44: Recycled PET production | C44: 0.007 | D44: — | E44: kg/FU
B45: Virgin HDPE production | C45: 0.00234 | D45: — | E45: kg/FU
B46: Primary aluminium | C46: — | D46: 0.0189704 | E46: kg/FU
B47: Pre-consumer recycled aluminium | C47: — | D47: 0.0065984 | E47: kg/FU
B48: Post-consumer recycled aluminium | C48: — | D48: 0.0156712 | E48: kg/FU
A49: Sheet rolling | B49: Aluminium material rolling | C49: — | D49: 0.04124 | E49: kg/FU
A50: Inbound transportation | B50: PET resin transport | C50: 0.014 | D50: — | E50: tkm/FU
B51: HDPE resin transport | C51: 0.00117 | D51: — | E51: tkm/FU
...

Sheet Emissions Factors
B1: CLIMATE-CHANGE EMISSION FACTORS
B2: Flow | C2: Factor | D2: Unit
B3: Virgin PET | C3: 2.19 | D3: kg CO2e/kg
B4: Recycled PET | C4: 1.01 | D4: kg CO2e/kg
B5: Virgin HDPE | C5: 1.8 | D5: kg CO2e/kg
B6: Primary aluminium | C6: 10.1 | D6: kg CO2e/kg
B7: Recycled aluminium — remelting | C7: 0.26 | D7: kg CO2e/kg
B8: Electricity | C8: 0.18344 | D8: kg CO2e/kWh
B9: Natural gas | C9: 0.066 | D9: kg CO2e/MJ
B10: Road freight — truck | C10: 0.1075 | D10: kg CO2e/tkm
B11: Aluminium sheet / rolling | C11: 0.412 | D11: kg CO2e/kg

Sheet LCIA
A1: LIFE CYCLE IMPACT ASSESSMENT FOR PACKAGING SYSTEM
A2: Stage | B2: Flow | C2: PET GWP (kg CO₂e/FU) | D2: Al GWP (kg CO₂e/FU)
A3: Material production | B3: Virgin PET | C3: =LCI!C15*'Emissions Factors'!C3 -> 0.04599 | D3: 0
B4: Recycled PET | C4: =LCI!C16*'Emissions Factors'!C4 -> 0.00707 | D4: 0
B5: Virgin HDPE | C5: =LCI!C17*'Emissions Factors'!C5 -> 0.004374 | D5: 0
B6: Primary aluminium | C6: 0 | D6: =LCI!C29*'Emissions Factors'!C6 -> 0.19160104
B7: Post-consumer recycled aluminium | C7: 0 | D7: =LCI!C31*'Emissions Factors'!C7 -> 0.004074512
B8: Pre-consumer recycled aluminium | C8: 0 | D8: =LCI!C30*'Emissions Factors'!C7 -> 0.001715584
A9: Sheet rolling | B9: Aluminium sheet processed | C9: 0 | D9: =LCI!C32*'Emissions Factors'!C11 -> 0.01699088
A10: Material transport | B10: PET/rPET resin road freight | C10: =LCI!C18*'Emissions Factors'!C10 -> 0.001505 | D10: 0
B11: HDPE resin road freight | C11: =LCI!C19*'Emissions Factors'!C10 -> 0.000125775 | D11: 0
B12: Aluminium sheet road freight | C12: 0 | D12: =LCI!C33*'Emissions Factors'!C10 -> 0.00221665
A13: Package manufacturing | B13: PET bottle electricity | C13: =LCI!C20*'Emissions Factors'!C8 -> 0.0087029806 | D13: 0
B14: HDPE closure electricity | C14: =LCI!C21*'Emissions Factors'!C8 -> 0.0006395819 | D14: 0
B15: Aluminium can electricity | C15: 0 | D15: =LCI!C34*'Emissions Factors'!C8 -> 0.012225146
B16: Aluminium can natural gas | C16: 0 | D16: =LCI!C35*'Emissions Factors'!C9 -> 0.014357706
A18: TOTAL GWP (kg CO₂e/FU) | C18: =SUM(C3:C16) -> 0.068407338 | D18: =SUM(D3:D16) -> 0.24318152
A19: Difference: aluminium minus PET (kg CO₂e/FU) | D19: =D18-C18 -> 0.17477418
A20: Ratio: aluminium / PET | D20: =IFERROR(D18/C18,0) -> 3.554904

Sheet Sensitivity Analysis
A1: STAGE 5 | RECYCLED-CONTENT SENSITIVITY ANALYSIS
A2: Functional unit: primary packaging for 1 L beverage | kg CO2e/FU | one-variable-at-a-time scenarios
A4: Model input | B4: PET | C4: Aluminium | D4: Notes
A5: Packaging material mass (kg) | B5: =SUM(LCI!C15:C16) -> 0.028 | C5: =SUM(LCI!C29:C31) -> 0.04124 | D5: Bottle body / four complete cans
A6: Virgin / primary EF (kg CO2e/kg) | B6: ='Emissions Factors'!C3 -> 2.19 | C6: ='Emissions Factors'!C6 -> 10.1 | D6: From Emissions Factors sheet
A7: Recycled EF (kg CO2e/kg) | B7: ='Emissions Factors'!C4 -> 1.01 | C7: ='Emissions Factors'!C7 -> 0.26 | D7: Al recycled EF: remelting-only proxy
A8: Constant GWP (kg CO2e/FU) | B8: =LCIA!C18-SUM(LCIA!C3:C4) -> 0.015347338 | C8: =LCIA!D18-SUM(LCIA!D6:D8) -> 0.045790382 | D8: LCIA total less virgin/recycled material GWP; remaining impacts fixed
A9: Base recycled fraction | B9: =LCI!C16/B5 -> 0.25 | C9: =SUM(LCI!C30:C31)/C5 -> 0.54 | D9: Original assumptions
A12: PET scenario | B12: Recycled share | C12: Virgin PET (kg) | D12: Recycled PET (kg) | E12: Total GWP (kg CO2e/FU) | F12: Change vs base
A13: Low recycled | B13: 0 | C13: =$B$5*(1-B13) -> 0.028 | D13: =$B$5*B13 -> 0 | E13: =C13*$B$6+D13*$B$7+$B$8 -> 0.076667338 | F13: =E13/$E$14-1 -> 0.12074728
A14: Base case | B14: =$B$9 -> 0.25 | C14: =$B$5*(1-B14) -> 0.021 | D14: =$B$5*B14 -> 0.007 | E14: =C14*$B$6+D14*$B$7+$B$8 -> 0.068407338 | F14: =E14/$E$14-1 -> 0
A15: High recycled | B15: 0.5 | C15: =$B$5*(1-B15) -> 0.014 | D15: =$B$5*B15 -> 0.014 | E15: =C15*$B$6+D15*$B$7+$B$8 -> 0.060147338 | F15: =E15/$E$14-1 -> -0.12074728
A18: Aluminium scenario | B18: Recycled share | C18: Primary Al (kg) | D18: Recycled Al (kg) | E18: Total GWP (kg CO2e/FU) | F18: Change vs base
A19: Low recycled | B19: 0.25 | C19: =$C$5*(1-B19) -> 0.03093 | D19: =$C$5*B19 -> 0.01031 | E19: =C19*$C$6+D19*$C$7+$C$8 -> 0.36086398 | F19: =E19/$E$20-1 -> 0.48392849
A20: Base case | B20: =$C$9 -> 0.54 | C20: =$C$5*(1-B20) -> 0.0189704 | D20: =$C$5*B20 -> 0.0222696 | E20: =C20*$C$6+D20*$C$7+$C$8 -> 0.24318152 | F20: =E20/$E$20-1 -> 0
A21: High recycled | B21: 0.75 | C21: =$C$5*(1-B21) -> 0.01031 | D21: =$C$5*B21 -> 0.03093 | E21: =C21*$C$6+D21*$C$7+$C$8 -> 0.15796318 | F21: =E21/$E$20-1 -> -0.35043097
A23: GWP across scenario
B24: PET | C24: Aluminium
A25: Low recycled | B25: =E13 -> 0.076667338 | C25: =E19 -> 0.36086398
A26: Base case | B26: =E14 -> 0.068407338 | C26: =E20 -> 0.24318152
A27: High recycled | B27: =E15 -> 0.060147338 | C27: =E21 -> 0.15796318
A30: GWP reduction across scenario
B31: PET | C31: Aluminium
A32: Low recycled | B32: =F13 -> 0.12074728 | C32: =F19 -> 0.48392849
A33: Base case | B33: =F14 -> 0 | C33: =F20 -> 0
A34: High recycled | B34: =F15 -> -0.12074728 | C34: =F21 -> -0.35043097

Sheet Results & Interpretation
A1: RESULTS
B2: PET | C2: ALUMINIUM
A3: TOTAL GWP (kg CO₂e/FU) | B3: =SUM(LCIA!C3:C16) -> 0.068407338 | C3: =SUM(LCIA!D3:D16) -> 0.24318152
A4: Difference: aluminium minus PET (kg CO₂e/FU) | C4: =C3-B3 -> 0.17477418
A5: Ratio: aluminium / PET | C5: =IFERROR(C3/B3,0) -> 3.554904
A7: CLIMATE IMPACT ANALYSIS
A9: Packaging System
A11: System | B11: GWP (kg CO₂e/FU) | C11: Packaging reference
A12: Pet bottle | B12: =B3 -> 0.068407338 | C12: 1 × 1 L PET bottle + HDPE closure
A13: Aluminium can | B13: =C3 -> 0.24318152 | C13: 4 × 250 mL aluminium cans
A15: Life-cycle stage (kg CO₂e/FU)
A17: Life-cycle stage | B17: PET | C17: Aluminium
A18: Material production | B18: =SUM(LCIA!C3:C5) -> 0.057434 | C18: =SUM(LCIA!D6:D8) -> 0.19739114
A19: Sheet rolling | B19: =0 -> 0 | C19: =LCIA!D9 -> 0.01699088
A20: Material transport | B20: =SUM(LCIA!C10:C11) -> 0.001630775 | C20: =LCIA!D12 -> 0.00221665
A21: Package manufacturing | B21: =SUM(LCIA!C13:C14) -> 0.0093425625 | C21: =SUM(LCIA!D15:D16) -> 0.026582852
A22: TOTAL | B22: =SUM(B18:B21) -> 0.068407338 | C22: =SUM(C18:C21) -> 0.24318152
A25: SENSITIVITY ANALYSIS
A27: GWP across scenario
B29: PET | C29: Aluminium
A30: Low recycled | B30: ='Sensitivity Analysis'!E13 -> 0.076667338 | C30: ='Sensitivity Analysis'!E19 -> 0.36086398
A31: Base case | B31: ='Sensitivity Analysis'!E14 -> 0.068407338 | C31: ='Sensitivity Analysis'!E20 -> 0.24318152
A32: High recycled | B32: ='Sensitivity Analysis'!E15 -> 0.060147338 | C32: ='Sensitivity Analysis'!E21 -> 0.15796318
A34: GWP reduction across scenario
B36: PET | C36: Aluminium
A37: Low recycled | B37: ='Sensitivity Analysis'!F13 -> 0.12074728 | C37: ='Sensitivity Analysis'!F19 -> 0.48392849
A38: Base case | B38: ='Sensitivity Analysis'!F14 -> 0 | C38: ='Sensitivity Analysis'!F20 -> 0
A39: High recycled | B39: ='Sensitivity Analysis'!F15 -> -0.12074728 | C39: ='Sensitivity Analysis'!F21 -> -0.35043097
A42: DISCUSSION & INTERPRETATION
A44: Guiding questions for discussion
A46: How does the cradle-to-gate climate-change impact of a PET bottle system compare with an aluminium can system? | B46: The PET bottle system has a cradle-to-gate climate-change impact of 0.06825 kg CO₂e/FU, compared with 0.24318 kg CO₂e/FU for the aluminium can system. Aluminium therefore exhibits approximately 3.56 times higher GWP than PET under the study's assumptions.
A47: Which life-cycle inputs drive the difference? | B47: Material production is the dominant contributor in both systems, accounting for 83.9% of PET GWP and 81.2% of aluminium GWP. Virgin PET production contributes 67.4% of the PET system's total impact, while primary aluminium production contributes 78.8% of the aluminium system's impact. The difference is primarily driven by the higher emission factor for primary aluminium (10.10 kg CO₂e/kg) compared with virgin PET (2.19 kg CO₂e/kg), alongside the respective material quantities.
A48: How sensitive is the comparison to recycled-content assumptions? | B48: Increasing recycled content reduces the modelled GWP of both systems. Raising recycled PET content from 25% to 50% reduces PET GWP by 12.1%, while increasing recycled aluminium content from 54% to 75% reduces aluminium GWP by 35.0%. Aluminium shows greater sensitivity to recycled-content assumptions. However, PET retains a lower modelled GWP across all tested scenarios, indicating that the comparative conclusion is stable within the selected scenario ranges.
A50: INTERPRETATION
A52: The screening LCA indicates that PET packaging has a lower cradle-to-gate climate-change impact than aluminium packaging for the defined functional unit of packaging for a 1 L beverage. Material production and recycled content are the key drivers. These conclusions are influenced by the selected secondary data, simplified recycling assumptions and excluded processes, and should not be generalised to all packaging applications.
A54: LIMITATIONS
A56: Limitation | B56: Description
A57: Processes | B57: This screening does not cover all relevant production processes for PET bottles and aluminium cans. PET preform manufacturing energy and aluminium production losses are not fully accounted for.
A58: System boundary | B58: The cradle-to-gate assessment excludes beverage filling, distribution, use and end-of-life treatment.
A59: Impact categories | B59: The assessment considers only climate-change impacts (GWP), excluding water consumption, resource depletion, toxicity and other environmental impacts.
...
